#try block will generate an error bcz x is not defined
try:
    print(x)
except:
    print("an axception occured")
    
